<?xml version="1.0"?>
<robot name="toio_style">

    <!--body-->
    <link name="base_link">
        <visual>
            <geometry>
                <box size="0.3 0.3 0.23" />
            </geometry>
            <material name="white">
                <color rgba="1.0 1.0 1.0 1.0" />
            </material>
        </visual>
        <collision>
            <geometry>
                <box size="0.3 0.3 0.23" />
            </geometry>
        </collision>
        <inertial>
            <mass value="1.0" />
            <inertia ixx="0.015" iyy="0.0375" izz="0.0375" ixy="0" ixz="0" iyz="0" />
        </inertial>
    </link>

    <!--front wheel -->
    <link name="front_wheel">
        <visual>
            <geometry>
                <cylinder length="0.05" radius="0.035" />
            </geometry>
            <material name="white" />
        </visual>
        <collision>
            <geometry>
                <cylinder length="0.05" radius="0.035" />
            </geometry>
        </collision>
        <inertial>
            <mass value="0.1" />
            <inertia ixx="5.1458e-5" iyy="5.1458e-5" izz="6.125e-5" ixy="0" ixz="0" iyz="0" />
        </inertial>
    </link>
    <joint name="front_wheel_joint" type="continuous">
        <axis xyz="0 0 1" />
        <parent link="base_link" />
        <child link="front_wheel" />
        <origin rpy="-1.5708 0 0" xyz="0.1 0 -0.1" />
    </joint>

    <!-- rear wheel -->
    <link name="back_wheel">
        <visual>
            <geometry>
                <cylinder length="0.05" radius="0.035" />
            </geometry>
            <material name="white" />
        </visual>
        <collision>
            <geometry>
                <cylinder length="0.05" radius="0.035" />
            </geometry>
        </collision>
        <inertial>
            <mass value="0.1" />
            <inertia ixx="5.1458e-5" iyy="5.1458e-5" izz="6.125e-5" ixy="0" ixz="0" iyz="0" />
        </inertial>
    </link>
    <joint name="back_wheel_joint" type="continuous">
        <axis xyz="0 0 1" />
        <parent link="base_link" />
        <child link="back_wheel" />
        <origin rpy="-1.5708 0 0" xyz="-0.1 0 -0.1" />
    </joint>

    <!--right wheel -->
    <link name="right_wheel">
        <visual>
            <geometry>
                <cylinder length="0.05" radius="0.035" />
            </geometry>
            <material name="gray">
                <color rgba="0.2 0.2 0.2 1" />
            </material>
        </visual>
        <collision>
            <geometry>
                <cylinder length="0.05" radius="0.035" />
            </geometry>
        </collision>
        <inertial>
            <mass value="0.1" />
            <inertia ixx="5.1458e-5" iyy="5.1458e-5" izz="6.125e-5" ixy="0" ixz="0" iyz="0" />
        </inertial>
    </link>
    <joint name="right_wheel_joint" type="continuous">
        <axis xyz="0 0 1" />
        <parent link="base_link" />
        <child link="right_wheel" />
        <origin rpy="-1.5708 0 0" xyz="0.0 -0.125 -.1" />
    </joint>

    <!-- left wheel -->
    <link name="left_wheel">
        <visual>
            <geometry>
                <cylinder length="0.05" radius="0.035" />
            </geometry>
            <material name="gray" />
        </visual>
        <collision>
            <geometry>
                <cylinder length="0.05" radius="0.035" />
            </geometry>
        </collision>
        <inertial>
            <mass value="0.1" />
            <inertia ixx="5.1458e-5" iyy="5.1458e-5" izz="6.125e-5" ixy="0" ixz="0" iyz="0" />
        </inertial>
    </link>
    <joint name="left_wheel_joint" type="continuous">
        <axis xyz="0 0 1" />
        <parent link="base_link" />
        <child link="left_wheel" />
        <origin rpy="-1.5708 0 0" xyz="0.0 0.125 -.1" />
    </joint>

    <!--plugin for ROS -->
    <gazebo>
        <plugin name="differential_drive_controller" filename="libgazebo_ros_diff_drive.so">
            <leftJoint>left_wheel_joint</leftJoint>
            <rightJoint>right_wheel_joint</rightJoint>
            <robotBaseFrame>base_link</robotBaseFrame>
            <wheelSeparation>0.25</wheelSeparation>
            <wheelDiameter>0.07</wheelDiameter>
            <updateRate>1</updateRate>
            <publishWheelJointState>true</publishWheelJointState>
        </plugin>
    </gazebo>
</robot>